2024-06-17 11:23:40,194 INFO    MainThread:21063 [wandb_setup.py:_flush():76] Current SDK version is 0.17.0
2024-06-17 11:23:40,194 INFO    MainThread:21063 [wandb_setup.py:_flush():76] Configure stats pid to 21063
2024-06-17 11:23:40,194 INFO    MainThread:21063 [wandb_setup.py:_flush():76] Loading settings from /home/zhaojinyue/.config/wandb/settings
2024-06-17 11:23:40,194 INFO    MainThread:21063 [wandb_setup.py:_flush():76] Loading settings from /home/zhaojinyue/workspace/intent-cluster/ablation/wandb/settings
2024-06-17 11:23:40,194 INFO    MainThread:21063 [wandb_setup.py:_flush():76] Loading settings from environment variables: {}
2024-06-17 11:23:40,195 INFO    MainThread:21063 [wandb_setup.py:_flush():76] Inferring run settings from compute environment: {'program': '<python with no main file>'}
2024-06-17 11:23:40,195 INFO    MainThread:21063 [wandb_setup.py:_flush():76] Applying login settings: {'api_key': '***REDACTED***'}
2024-06-17 11:23:40,195 INFO    MainThread:21063 [wandb_setup.py:_flush():76] Applying login settings: {'api_key': '***REDACTED***'}
2024-06-17 11:23:40,195 INFO    MainThread:21063 [wandb_setup.py:_flush():76] Applying login settings: {'anonymous': 'must'}
2024-06-17 11:23:40,195 INFO    MainThread:21063 [wandb_init.py:_log_setup():520] Logging user logs to /home/zhaojinyue/workspace/intent-cluster/ablation/wandb/run-20240617_112340-rp7zo7e2/logs/debug.log
2024-06-17 11:23:40,195 INFO    MainThread:21063 [wandb_init.py:_log_setup():521] Logging internal logs to /home/zhaojinyue/workspace/intent-cluster/ablation/wandb/run-20240617_112340-rp7zo7e2/logs/debug-internal.log
2024-06-17 11:23:40,195 INFO    MainThread:21063 [wandb_init.py:init():560] calling init triggers
2024-06-17 11:23:40,195 INFO    MainThread:21063 [wandb_init.py:init():567] wandb.init called with sweep_config: {}
config: {'BATCH_SIZE': 25, 'EPOCHES': 100, 'dataset_name': 'banking', 'model_name': 'VAE_semi', 'n': 58, 'num_warmup_rate': 0.05, 'seed': 42}
2024-06-17 11:23:40,195 INFO    MainThread:21063 [wandb_init.py:init():610] starting backend
2024-06-17 11:23:40,195 INFO    MainThread:21063 [wandb_init.py:init():614] setting up manager
2024-06-17 11:23:40,203 INFO    MainThread:21063 [backend.py:_multiprocessing_setup():105] multiprocessing start_methods=fork,spawn,forkserver, using: spawn
2024-06-17 11:23:40,236 INFO    MainThread:21063 [wandb_init.py:init():622] backend started and connected
2024-06-17 11:23:40,243 INFO    MainThread:21063 [wandb_init.py:init():711] updated telemetry
2024-06-17 11:23:40,246 INFO    MainThread:21063 [wandb_init.py:init():744] communicating run to backend with 90.0 second timeout
2024-06-17 11:24:14,858 INFO    Thread-4 (wrapped_target):21063 [retry.py:__call__():172] Retry attempt failed:
Traceback (most recent call last):
  File "/home/zhaojinyue/conda/yes/lib/python3.11/site-packages/urllib3/connection.py", line 174, in _new_conn
    conn = connection.create_connection(
           ^^^^^^^^^^^^^^^^^^^^^^^^^^^^^
  File "/home/zhaojinyue/conda/yes/lib/python3.11/site-packages/urllib3/util/connection.py", line 95, in create_connection
    raise err
  File "/home/zhaojinyue/conda/yes/lib/python3.11/site-packages/urllib3/util/connection.py", line 85, in create_connection
    sock.connect(sa)
TimeoutError: timed out

During handling of the above exception, another exception occurred:

Traceback (most recent call last):
  File "/home/zhaojinyue/conda/yes/lib/python3.11/site-packages/urllib3/connectionpool.py", line 714, in urlopen
    httplib_response = self._make_request(
                       ^^^^^^^^^^^^^^^^^^^
  File "/home/zhaojinyue/conda/yes/lib/python3.11/site-packages/urllib3/connectionpool.py", line 403, in _make_request
    self._validate_conn(conn)
  File "/home/zhaojinyue/conda/yes/lib/python3.11/site-packages/urllib3/connectionpool.py", line 1053, in _validate_conn
    conn.connect()
  File "/home/zhaojinyue/conda/yes/lib/python3.11/site-packages/urllib3/connection.py", line 363, in connect
    self.sock = conn = self._new_conn()
                       ^^^^^^^^^^^^^^^^
  File "/home/zhaojinyue/conda/yes/lib/python3.11/site-packages/urllib3/connection.py", line 179, in _new_conn
    raise ConnectTimeoutError(
urllib3.exceptions.ConnectTimeoutError: (<urllib3.connection.HTTPSConnection object at 0x7f48de3aa390>, 'Connection to api.wandb.ai timed out. (connect timeout=20)')

During handling of the above exception, another exception occurred:

Traceback (most recent call last):
  File "/home/zhaojinyue/conda/yes/lib/python3.11/site-packages/requests/adapters.py", line 486, in send
    resp = conn.urlopen(
           ^^^^^^^^^^^^^
  File "/home/zhaojinyue/conda/yes/lib/python3.11/site-packages/urllib3/connectionpool.py", line 798, in urlopen
    retries = retries.increment(
              ^^^^^^^^^^^^^^^^^^
  File "/home/zhaojinyue/conda/yes/lib/python3.11/site-packages/urllib3/util/retry.py", line 592, in increment
    raise MaxRetryError(_pool, url, error or ResponseError(cause))
urllib3.exceptions.MaxRetryError: HTTPSConnectionPool(host='api.wandb.ai', port=443): Max retries exceeded with url: /graphql (Caused by ConnectTimeoutError(<urllib3.connection.HTTPSConnection object at 0x7f48de3aa390>, 'Connection to api.wandb.ai timed out. (connect timeout=20)'))

During handling of the above exception, another exception occurred:

Traceback (most recent call last):
  File "/home/zhaojinyue/conda/yes/lib/python3.11/site-packages/wandb/sdk/lib/retry.py", line 131, in __call__
    result = self._call_fn(*args, **kwargs)
             ^^^^^^^^^^^^^^^^^^^^^^^^^^^^^^
  File "/home/zhaojinyue/conda/yes/lib/python3.11/site-packages/wandb/sdk/internal/internal_api.py", line 340, in execute
    return self.client.execute(*args, **kwargs)  # type: ignore
           ^^^^^^^^^^^^^^^^^^^^^^^^^^^^^^^^^^^^
  File "/home/zhaojinyue/conda/yes/lib/python3.11/site-packages/wandb/vendor/gql-0.2.0/wandb_gql/client.py", line 52, in execute
    result = self._get_result(document, *args, **kwargs)
             ^^^^^^^^^^^^^^^^^^^^^^^^^^^^^^^^^^^^^^^^^^^
  File "/home/zhaojinyue/conda/yes/lib/python3.11/site-packages/wandb/vendor/gql-0.2.0/wandb_gql/client.py", line 60, in _get_result
    return self.transport.execute(document, *args, **kwargs)
           ^^^^^^^^^^^^^^^^^^^^^^^^^^^^^^^^^^^^^^^^^^^^^^^^^
  File "/home/zhaojinyue/conda/yes/lib/python3.11/site-packages/wandb/sdk/lib/gql_request.py", line 58, in execute
    request = self.session.post(self.url, **post_args)
              ^^^^^^^^^^^^^^^^^^^^^^^^^^^^^^^^^^^^^^^^
  File "/home/zhaojinyue/conda/yes/lib/python3.11/site-packages/requests/sessions.py", line 637, in post
    return self.request("POST", url, data=data, json=json, **kwargs)
           ^^^^^^^^^^^^^^^^^^^^^^^^^^^^^^^^^^^^^^^^^^^^^^^^^^^^^^^^^
  File "/home/zhaojinyue/conda/yes/lib/python3.11/site-packages/requests/sessions.py", line 589, in request
    resp = self.send(prep, **send_kwargs)
           ^^^^^^^^^^^^^^^^^^^^^^^^^^^^^^
  File "/home/zhaojinyue/conda/yes/lib/python3.11/site-packages/requests/sessions.py", line 703, in send
    r = adapter.send(request, **kwargs)
        ^^^^^^^^^^^^^^^^^^^^^^^^^^^^^^^
  File "/home/zhaojinyue/conda/yes/lib/python3.11/site-packages/requests/adapters.py", line 507, in send
    raise ConnectTimeout(e, request=request)
requests.exceptions.ConnectTimeout: HTTPSConnectionPool(host='api.wandb.ai', port=443): Max retries exceeded with url: /graphql (Caused by ConnectTimeoutError(<urllib3.connection.HTTPSConnection object at 0x7f48de3aa390>, 'Connection to api.wandb.ai timed out. (connect timeout=20)'))
2024-06-17 11:24:29,822 INFO    Thread-5 (wrapped_target):21063 [retry.py:__call__():172] Retry attempt failed:
Traceback (most recent call last):
  File "/home/zhaojinyue/conda/yes/lib/python3.11/site-packages/urllib3/connection.py", line 174, in _new_conn
    conn = connection.create_connection(
           ^^^^^^^^^^^^^^^^^^^^^^^^^^^^^
  File "/home/zhaojinyue/conda/yes/lib/python3.11/site-packages/urllib3/util/connection.py", line 95, in create_connection
    raise err
  File "/home/zhaojinyue/conda/yes/lib/python3.11/site-packages/urllib3/util/connection.py", line 85, in create_connection
    sock.connect(sa)
TimeoutError: timed out

During handling of the above exception, another exception occurred:

Traceback (most recent call last):
  File "/home/zhaojinyue/conda/yes/lib/python3.11/site-packages/urllib3/connectionpool.py", line 714, in urlopen
    httplib_response = self._make_request(
                       ^^^^^^^^^^^^^^^^^^^
  File "/home/zhaojinyue/conda/yes/lib/python3.11/site-packages/urllib3/connectionpool.py", line 403, in _make_request
    self._validate_conn(conn)
  File "/home/zhaojinyue/conda/yes/lib/python3.11/site-packages/urllib3/connectionpool.py", line 1053, in _validate_conn
    conn.connect()
  File "/home/zhaojinyue/conda/yes/lib/python3.11/site-packages/urllib3/connection.py", line 363, in connect
    self.sock = conn = self._new_conn()
                       ^^^^^^^^^^^^^^^^
  File "/home/zhaojinyue/conda/yes/lib/python3.11/site-packages/urllib3/connection.py", line 179, in _new_conn
    raise ConnectTimeoutError(
urllib3.exceptions.ConnectTimeoutError: (<urllib3.connection.HTTPSConnection object at 0x7f48e080bad0>, 'Connection to api.wandb.ai timed out. (connect timeout=20)')

During handling of the above exception, another exception occurred:

Traceback (most recent call last):
  File "/home/zhaojinyue/conda/yes/lib/python3.11/site-packages/requests/adapters.py", line 486, in send
    resp = conn.urlopen(
           ^^^^^^^^^^^^^
  File "/home/zhaojinyue/conda/yes/lib/python3.11/site-packages/urllib3/connectionpool.py", line 798, in urlopen
    retries = retries.increment(
              ^^^^^^^^^^^^^^^^^^
  File "/home/zhaojinyue/conda/yes/lib/python3.11/site-packages/urllib3/util/retry.py", line 592, in increment
    raise MaxRetryError(_pool, url, error or ResponseError(cause))
urllib3.exceptions.MaxRetryError: HTTPSConnectionPool(host='api.wandb.ai', port=443): Max retries exceeded with url: /graphql (Caused by ConnectTimeoutError(<urllib3.connection.HTTPSConnection object at 0x7f48e080bad0>, 'Connection to api.wandb.ai timed out. (connect timeout=20)'))

During handling of the above exception, another exception occurred:

Traceback (most recent call last):
  File "/home/zhaojinyue/conda/yes/lib/python3.11/site-packages/wandb/sdk/lib/retry.py", line 131, in __call__
    result = self._call_fn(*args, **kwargs)
             ^^^^^^^^^^^^^^^^^^^^^^^^^^^^^^
  File "/home/zhaojinyue/conda/yes/lib/python3.11/site-packages/wandb/sdk/internal/internal_api.py", line 340, in execute
    return self.client.execute(*args, **kwargs)  # type: ignore
           ^^^^^^^^^^^^^^^^^^^^^^^^^^^^^^^^^^^^
  File "/home/zhaojinyue/conda/yes/lib/python3.11/site-packages/wandb/vendor/gql-0.2.0/wandb_gql/client.py", line 52, in execute
    result = self._get_result(document, *args, **kwargs)
             ^^^^^^^^^^^^^^^^^^^^^^^^^^^^^^^^^^^^^^^^^^^
  File "/home/zhaojinyue/conda/yes/lib/python3.11/site-packages/wandb/vendor/gql-0.2.0/wandb_gql/client.py", line 60, in _get_result
    return self.transport.execute(document, *args, **kwargs)
           ^^^^^^^^^^^^^^^^^^^^^^^^^^^^^^^^^^^^^^^^^^^^^^^^^
  File "/home/zhaojinyue/conda/yes/lib/python3.11/site-packages/wandb/sdk/lib/gql_request.py", line 58, in execute
    request = self.session.post(self.url, **post_args)
              ^^^^^^^^^^^^^^^^^^^^^^^^^^^^^^^^^^^^^^^^
  File "/home/zhaojinyue/conda/yes/lib/python3.11/site-packages/requests/sessions.py", line 637, in post
    return self.request("POST", url, data=data, json=json, **kwargs)
           ^^^^^^^^^^^^^^^^^^^^^^^^^^^^^^^^^^^^^^^^^^^^^^^^^^^^^^^^^
  File "/home/zhaojinyue/conda/yes/lib/python3.11/site-packages/requests/sessions.py", line 589, in request
    resp = self.send(prep, **send_kwargs)
           ^^^^^^^^^^^^^^^^^^^^^^^^^^^^^^
  File "/home/zhaojinyue/conda/yes/lib/python3.11/site-packages/requests/sessions.py", line 703, in send
    r = adapter.send(request, **kwargs)
        ^^^^^^^^^^^^^^^^^^^^^^^^^^^^^^^
  File "/home/zhaojinyue/conda/yes/lib/python3.11/site-packages/requests/adapters.py", line 507, in send
    raise ConnectTimeout(e, request=request)
requests.exceptions.ConnectTimeout: HTTPSConnectionPool(host='api.wandb.ai', port=443): Max retries exceeded with url: /graphql (Caused by ConnectTimeoutError(<urllib3.connection.HTTPSConnection object at 0x7f48e080bad0>, 'Connection to api.wandb.ai timed out. (connect timeout=20)'))
2024-06-17 11:25:10,361 ERROR   MainThread:21063 [wandb_init.py:init():770] encountered error: Run initialization has timed out after 90.0 sec. 
Please refer to the documentation for additional information: https://docs.wandb.ai/guides/track/tracking-faq#initstarterror-error-communicating-with-wandb-process-
2024-06-17 11:25:10,361 ERROR   MainThread:21063 [wandb_init.py:init():1174] error in wandb.init()
Traceback (most recent call last):
  File "/home/zhaojinyue/conda/yes/lib/python3.11/site-packages/wandb/sdk/wandb_init.py", line 1164, in init
    return wi.init()
           ^^^^^^^^^
  File "/home/zhaojinyue/conda/yes/lib/python3.11/site-packages/wandb/sdk/wandb_init.py", line 776, in init
    raise error
wandb.errors.CommError: Run initialization has timed out after 90.0 sec. 
Please refer to the documentation for additional information: https://docs.wandb.ai/guides/track/tracking-faq#initstarterror-error-communicating-with-wandb-process-
